Workbook

Sheet Импорт
A1: Объект размещения | B1: Субарендатор | C1: Оборудование | D1: Кол-во | E1: Статус размещения | F1: Высота подвеса | G1: Способ установки / прокладки
A2: =IF(OR(ISBLANK(Таблица2[[#This Row],[Оборудование]]),Таблица2[[#This Row],[Оборудование]]=""),"",'Спецификация для запроса ТУ'!$D$7) -> -?- | B2: =IF(OR(ISBLANK(Таблица2[[#This Row],[Оборудование]]),Таблица2[[#This Row],[Оборудование]]=""),"",'Спецификация для запроса ТУ'!$D$6) -> -?- | C2: =IF(ISBLANK('Спецификация для запроса ТУ'!C13),"",'Спецификация для запроса ТУ'!C13) -> Радиочастотный кабель | D2: =IF(OR(ISBLANK(Таблица2[[#This Row],[Оборудование]]),Таблица2[[#This Row],[Оборудование]]=""),"",'Спецификация для запроса ТУ'!F13) -> -?- | E2: =IF(OR(ISBLANK(Таблица2[[#This Row],[Оборудование]]),Таблица2[[#This Row],[Оборудование]]=""),"",'Спецификация для запроса ТУ'!H13) -> -?- | F2: =IF(IF(OR(ISBLANK(Таблица2[[#This Row],[Оборудование]]),Таблица2[[#This Row],[Оборудование]]=""),"",'Спецификация для запроса ТУ'!G13)="-","",IF(OR(ISBLANK(Таблица2[[#This Row],[Оборудование]]),Таблица2[[#This Row],[Оборудование]]=""),"",'Спецификация для запроса ТУ'!G13)) | G2: =IF(OR(ISBLANK(Таблица2[[#This Row],[Оборудование]]),Таблица2[[#This Row],[Оборудование]]=""),"","Не задано") -> Не задано
A3: =IF(OR(ISBLANK(Таблица2[[#This Row],[Оборудование]]),Таблица2[[#This Row],[Оборудование]]=""),"",'Спецификация для запроса ТУ'!$D$7) -> -?- | B3: =IF(OR(ISBLANK(Таблица2[[#This Row],[Оборудование]]),Таблица2[[#This Row],[Оборудование]]=""),"",'Спецификация для запроса ТУ'!$D$6) -> -?- | C3: =IF(ISBLANK('Спецификация для запроса ТУ'!C14),"",'Спецификация для запроса ТУ'!C14) -> Оптический кабель | D3: =IF(OR(ISBLANK(Таблица2[[#This Row],[Оборудование]]),Таблица2[[#This Row],[Оборудование]]=""),"",'Спецификация для запроса ТУ'!F14) -> -?- | E3: =IF(OR(ISBLANK(Таблица2[[#This Row],[Оборудование]]),Таблица2[[#This Row],[Оборудование]]=""),"",'Спецификация для запроса ТУ'!H14) -> -?- | F3: =IF(IF(OR(ISBLANK(Таблица2[[#This Row],[Оборудование]]),Таблица2[[#This Row],[Оборудование]]=""),"",'Спецификация для запроса ТУ'!G14)="-","",IF(OR(ISBLANK(Таблица2[[#This Row],[Оборудование]]),Таблица2[[#This Row],[Оборудование]]=""),"",'Спецификация для запроса ТУ'!G14)) | G3: =IF(OR(ISBLANK(Таблица2[[#This Row],[Оборудование]]),Таблица2[[#This Row],[Оборудование]]=""),"","Не задано") -> Не задано
A4: =IF(OR(ISBLANK(Таблица2[[#This Row],[Оборудование]]),Таблица2[[#This Row],[Оборудование]]=""),"",'Спецификация для запроса ТУ'!$D$7) -> -?- | B4: =IF(OR(ISBLANK(Таблица2[[#This Row],[Оборудование]]),Таблица2[[#This Row],[Оборудование]]=""),"",'Спецификация для запроса ТУ'!$D$6) -> -?- | C4: =IF(ISBLANK('Спецификация для запроса ТУ'!C15),"",'Спецификация для запроса ТУ'!C15) -> Кабель питания (DC) | D4: =IF(OR(ISBLANK(Таблица2[[#This Row],[Оборудование]]),Таблица2[[#This Row],[Оборудование]]=""),"",'Спецификация для запроса ТУ'!F15) -> -?- | E4: =IF(OR(ISBLANK(Таблица2[[#This Row],[Оборудование]]),Таблица2[[#This Row],[Оборудование]]=""),"",'Спецификация для запроса ТУ'!H15) -> -?- | F4: =IF(IF(OR(ISBLANK(Таблица2[[#This Row],[Оборудование]]),Таблица2[[#This Row],[Оборудование]]=""),"",'Спецификация для запроса ТУ'!G15)="-","",IF(OR(ISBLANK(Таблица2[[#This Row],[Оборудование]]),Таблица2[[#This Row],[Оборудование]]=""),"",'Спецификация для запроса ТУ'!G15)) | G4: =IF(OR(ISBLANK(Таблица2[[#This Row],[Оборудование]]),Таблица2[[#This Row],[Оборудование]]=""),"","Не задано") -> Не задано
A5: =IF(OR(ISBLANK(Таблица2[[#This Row],[Оборудование]]),Таблица2[[#This Row],[Оборудование]]=""),"",'Спецификация для запроса ТУ'!$D$7) -> -?- | B5: =IF(OR(ISBLANK(Таблица2[[#This Row],[Оборудование]]),Таблица2[[#This Row],[Оборудование]]=""),"",'Спецификация для запроса ТУ'!$D$6) -> -?- | C5: =IF(ISBLANK('Спецификация для запроса ТУ'!C16),"",'Спецификация для запроса ТУ'!C16) -> Кабель управления RET | D5: =IF(OR(ISBLANK(Таблица2[[#This Row],[Оборудование]]),Таблица2[[#This Row],[Оборудование]]=""),"",'Спецификация для запроса ТУ'!F16) -> -?- | E5: =IF(OR(ISBLANK(Таблица2[[#This Row],[Оборудование]]),Таблица2[[#This Row],[Оборудование]]=""),"",'Спецификация для запроса ТУ'!H16) -> -?- | F5: =IF(IF(OR(ISBLANK(Таблица2[[#This Row],[Оборудование]]),Таблица2[[#This Row],[Оборудование]]=""),"",'Спецификация для запроса ТУ'!G16)="-","",IF(OR(ISBLANK(Таблица2[[#This Row],[Оборудование]]),Таблица2[[#This Row],[Оборудование]]=""),"",'Спецификация для запроса ТУ'!G16)) | G5: =IF(OR(ISBLANK(Таблица2[[#This Row],[Оборудование]]),Таблица2[[#This Row],[Оборудование]]=""),"","Не задано") -> Не задано
A6: =IF(OR(ISBLANK(Таблица2[[#This Row],[Оборудование]]),Таблица2[[#This Row],[Оборудование]]=""),"",'Спецификация для запроса ТУ'!$D$7) | B6: =IF(OR(ISBLANK(Таблица2[[#This Row],[Оборудование]]),Таблица2[[#This Row],[Оборудование]]=""),"",'Спецификация для запроса ТУ'!$D$6) | C6: =IF(ISBLANK('Спецификация для запроса ТУ'!C17),"",'Спецификация для запроса ТУ'!C17) | D6: =IF(OR(ISBLANK(Таблица2[[#This Row],[Оборудование]]),Таблица2[[#This Row],[Оборудование]]=""),"",'Спецификация для запроса ТУ'!F17) | E6: =IF(OR(ISBLANK(Таблица2[[#This Row],[Оборудование]]),Таблица2[[#This Row],[Оборудование]]=""),"",'Спецификация для запроса ТУ'!H17) | F6: =IF(IF(OR(ISBLANK(Таблица2[[#This Row],[Оборудование]]),Таблица2[[#This Row],[Оборудование]]=""),"",'Спецификация для запроса ТУ'!G17)="-","",IF(OR(ISBLANK(Таблица2[[#This Row],[Оборудование]]),Таблица2[[#This Row],[Оборудование]]=""),"",'Спецификация для запроса ТУ'!G17)) | G6: =IF(OR(ISBLANK(Таблица2[[#This Row],[Оборудование]]),Таблица2[[#This Row],[Оборудование]]=""),"","Не задано")
A7: =IF(OR(ISBLANK(Таблица2[[#This Row],[Оборудование]]),Таблица2[[#This Row],[Оборудование]]=""),"",'Спецификация для запроса ТУ'!$D$7) | B7: =IF(OR(ISBLANK(Таблица2[[#This Row],[Оборудование]]),Таблица2[[#This Row],[Оборудование]]=""),"",'Спецификация для запроса ТУ'!$D$6) | C7: =IF(ISBLANK('Спецификация для запроса ТУ'!C18),"",'Спецификация для запроса ТУ'!C18) | D7: =IF(OR(ISBLANK(Таблица2[[#This Row],[Оборудование]]),Таблица2[[#This Row],[Оборудование]]=""),"",'Спецификация для запроса ТУ'!F18) | E7: =IF(OR(ISBLANK(Таблица2[[#This Row],[Оборудование]]),Таблица2[[#This Row],[Оборудование]]=""),"",'Спецификация для запроса ТУ'!H18) | F7: =IF(IF(OR(ISBLANK(Таблица2[[#This Row],[Оборудование]]),Таблица2[[#This Row],[Оборудование]]=""),"",'Спецификация для запроса ТУ'!G18)="-","",IF(OR(ISBLANK(Таблица2[[#This Row],[Оборудование]]),Таблица2[[#This Row],[Оборудование]]=""),"",'Спецификация для запроса ТУ'!G18)) | G7: =IF(OR(ISBLANK(Таблица2[[#This Row],[Оборудование]]),Таблица2[[#This Row],[Оборудование]]=""),"","Не задано")
A8: =IF(OR(ISBLANK(Таблица2[[#This Row],[Оборудование]]),Таблица2[[#This Row],[Оборудование]]=""),"",'Спецификация для запроса ТУ'!$D$7) | B8: =IF(OR(ISBLANK(Таблица2[[#This Row],[Оборудование]]),Таблица2[[#This Row],[Оборудование]]=""),"",'Спецификация для запроса ТУ'!$D$6) | C8: =IF(ISBLANK('Спецификация для запроса ТУ'!C19),"",'Спецификация для запроса ТУ'!C19) | D8: =IF(OR(ISBLANK(Таблица2[[#This Row],[Оборудование]]),Таблица2[[#This Row],[Оборудование]]=""),"",'Спецификация для запроса ТУ'!F19) | E8: =IF(OR(ISBLANK(Таблица2[[#This Row],[Оборудование]]),Таблица2[[#This Row],[Оборудование]]=""),"",'Спецификация для запроса ТУ'!H19) | F8: =IF(IF(OR(ISBLANK(Таблица2[[#This Row],[Оборудование]]),Таблица2[[#This Row],[Оборудование]]=""),"",'Спецификация для запроса ТУ'!G19)="-","",IF(OR(ISBLANK(Таблица2[[#This Row],[Оборудование]]),Таблица2[[#This Row],[Оборудование]]=""),"",'Спецификация для запроса ТУ'!G19)) | G8: =IF(OR(ISBLANK(Таблица2[[#This Row],[Оборудование]]),Таблица2[[#This Row],[Оборудование]]=""),"","Не задано")
A9: =IF(OR(ISBLANK(Таблица2[[#This Row],[Оборудование]]),Таблица2[[#This Row],[Оборудование]]=""),"",'Спецификация для запроса ТУ'!$D$7) | B9: =IF(OR(ISBLANK(Таблица2[[#This Row],[Оборудование]]),Таблица2[[#This Row],[Оборудование]]=""),"",'Спецификация для запроса ТУ'!$D$6) | C9: =IF(ISBLANK('Спецификация для запроса ТУ'!C20),"",'Спецификация для запроса ТУ'!C20) | D9: =IF(OR(ISBLANK(Таблица2[[#This Row],[Оборудование]]),Таблица2[[#This Row],[Оборудование]]=""),"",'Спецификация для запроса ТУ'!F20) | E9: =IF(OR(ISBLANK(Таблица2[[#This Row],[Оборудование]]),Таблица2[[#This Row],[Оборудование]]=""),"",'Спецификация для запроса ТУ'!H20) | F9: =IF(IF(OR(ISBLANK(Таблица2[[#This Row],[Оборудование]]),Таблица2[[#This Row],[Оборудование]]=""),"",'Спецификация для запроса ТУ'!G20)="-","",IF(OR(ISBLANK(Таблица2[[#This Row],[Оборудование]]),Таблица2[[#This Row],[Оборудование]]=""),"",'Спецификация для запроса ТУ'!G20)) | G9: =IF(OR(ISBLANK(Таблица2[[#This Row],[Оборудование]]),Таблица2[[#This Row],[Оборудование]]=""),"","Не задано")
A10: =IF(OR(ISBLANK(Таблица2[[#This Row],[Оборудование]]),Таблица2[[#This Row],[Оборудование]]=""),"",'Спецификация для запроса ТУ'!$D$7) | B10: =IF(OR(ISBLANK(Таблица2[[#This Row],[Оборудование]]),Таблица2[[#This Row],[Оборудование]]=""),"",'Спецификация для запроса ТУ'!$D$6) | C10: =IF(ISBLANK('Спецификация для запроса ТУ'!C21),"",'Спецификация для запроса ТУ'!C21) | D10: =IF(OR(ISBLANK(Таблица2[[#This Row],[Оборудование]]),Таблица2[[#This Row],[Оборудование]]=""),"",'Спецификация для запроса ТУ'!F21) | E10: =IF(OR(ISBLANK(Таблица2[[#This Row],[Оборудование]]),Таблица2[[#This Row],[Оборудование]]=""),"",'Спецификация для запроса ТУ'!H21) | F10: =IF(IF(OR(ISBLANK(Таблица2[[#This Row],[Оборудование]]),Таблица2[[#This Row],[Оборудование]]=""),"",'Спецификация для запроса ТУ'!G21)="-","",IF(OR(ISBLANK(Таблица2[[#This Row],[Оборудование]]),Таблица2[[#This Row],[Оборудование]]=""),"",'Спецификация для запроса ТУ'!G21)) | G10: =IF(OR(ISBLANK(Таблица2[[#This Row],[Оборудование]]),Таблица2[[#This Row],[Оборудование]]=""),"","Не задано")
A11: =IF(OR(ISBLANK(Таблица2[[#This Row],[Оборудование]]),Таблица2[[#This Row],[Оборудование]]=""),"",'Спецификация для запроса ТУ'!$D$7) | B11: =IF(OR(ISBLANK(Таблица2[[#This Row],[Оборудование]]),Таблица2[[#This Row],[Оборудование]]=""),"",'Спецификация для запроса ТУ'!$D$6) | C11: =IF(ISBLANK('Спецификация для запроса ТУ'!C22),"",'Спецификация для запроса ТУ'!C22) | D11: =IF(OR(ISBLANK(Таблица2[[#This Row],[Оборудование]]),Таблица2[[#This Row],[Оборудование]]=""),"",'Спецификация для запроса ТУ'!F22) | E11: =IF(OR(ISBLANK(Таблица2[[#This Row],[Оборудование]]),Таблица2[[#This Row],[Оборудование]]=""),"",'Спецификация для запроса ТУ'!H22) | F11: =IF(IF(OR(ISBLANK(Таблица2[[#This Row],[Оборудование]]),Таблица2[[#This Row],[Оборудование]]=""),"",'Спецификация для запроса ТУ'!G22)="-","",IF(OR(ISBLANK(Таблица2[[#This Row],[Оборудование]]),Таблица2[[#This Row],[Оборудование]]=""),"",'Спецификация для запроса ТУ'!G22)) | G11: =IF(OR(ISBLANK(Таблица2[[#This Row],[Оборудование]]),Таблица2[[#This Row],[Оборудование]]=""),"","Не задано")
A12: =IF(OR(ISBLANK(Таблица2[[#This Row],[Оборудование]]),Таблица2[[#This Row],[Оборудование]]=""),"",'Спецификация для запроса ТУ'!$D$7) | B12: =IF(OR(ISBLANK(Таблица2[[#This Row],[Оборудование]]),Таблица2[[#This Row],[Оборудование]]=""),"",'Спецификация для запроса ТУ'!$D$6) | C12: =IF(ISBLANK('Спецификация для запроса ТУ'!C23),"",'Спецификация для запроса ТУ'!C23) | D12: =IF(OR(ISBLANK(Таблица2[[#This Row],[Оборудование]]),Таблица2[[#This Row],[Оборудование]]=""),"",'Спецификация для запроса ТУ'!F23) | E12: =IF(OR(ISBLANK(Таблица2[[#This Row],[Оборудование]]),Таблица2[[#This Row],[Оборудование]]=""),"",'Спецификация для запроса ТУ'!H23) | F12: =IF(IF(OR(ISBLANK(Таблица2[[#This Row],[Оборудование]]),Таблица2[[#This Row],[Оборудование]]=""),"",'Спецификация для запроса ТУ'!G23)="-","",IF(OR(ISBLANK(Таблица2[[#This Row],[Оборудование]]),Таблица2[[#This Row],[Оборудование]]=""),"",'Спецификация для запроса ТУ'!G23)) | G12: =IF(OR(ISBLANK(Таблица2[[#This Row],[Оборудование]]),Таблица2[[#This Row],[Оборудование]]=""),"","Не задано")
A13: =IF(OR(ISBLANK(Таблица2[[#This Row],[Оборудование]]),Таблица2[[#This Row],[Оборудование]]=""),"",'Спецификация для запроса ТУ'!$D$7) | B13: =IF(OR(ISBLANK(Таблица2[[#This Row],[Оборудование]]),Таблица2[[#This Row],[Оборудование]]=""),"",'Спецификация для запроса ТУ'!$D$6) | C13: =IF(ISBLANK('Спецификация для запроса ТУ'!C24),"",'Спецификация для запроса ТУ'!C24) | D13: =IF(OR(ISBLANK(Таблица2[[#This Row],[Оборудование]]),Таблица2[[#This Row],[Оборудование]]=""),"",'Спецификация для запроса ТУ'!F24) | E13: =IF(OR(ISBLANK(Таблица2[[#This Row],[Оборудование]]),Таблица2[[#This Row],[Оборудование]]=""),"",'Спецификация для запроса ТУ'!H24) | F13: =IF(IF(OR(ISBLANK(Таблица2[[#This Row],[Оборудование]]),Таблица2[[#This Row],[Оборудование]]=""),"",'Спецификация для запроса ТУ'!G24)="-","",IF(OR(ISBLANK(Таблица2[[#This Row],[Оборудование]]),Таблица2[[#This Row],[Оборудование]]=""),"",'Спецификация для запроса ТУ'!G24)) | G13: =IF(OR(ISBLANK(Таблица2[[#This Row],[Оборудование]]),Таблица2[[#This Row],[Оборудование]]=""),"","Не задано")
... A34: =IF(OR(ISBLANK(Таблица2[[#This Row],[Оборудование]]),Таблица2[[#This Row],[Оборудование]]=""),"",'Спецификация для запроса ТУ'!$D$7) | B34: =IF(OR(ISBLANK(Таблица2[[#This Row],[Оборудование]]),Таблица2[[#This Row],[Оборудование]]=""),"",'Спецификация для запроса ТУ'!$D$6) | C34: =IF(ISBLANK('Спецификация для запроса ТУ'!C45),"",'Спецификация для запроса ТУ'!C45) | D34: =IF(OR(ISBLANK(Таблица2[[#This Row],[Оборудование]]),Таблица2[[#This Row],[Оборудование]]=""),"",'Спецификация для запроса ТУ'!F45) | E34: =IF(OR(ISBLANK(Таблица2[[#This Row],[Оборудование]]),Таблица2[[#This Row],[Оборудование]]=""),"",'Спецификация для запроса ТУ'!H45) | F34: =IF(IF(OR(ISBLANK(Таблица2[[#This Row],[Оборудование]]),Таблица2[[#This Row],[Оборудование]]=""),"",'Спецификация для запроса ТУ'!G45)="-","",IF(OR(ISBLANK(Таблица2[[#This Row],[Оборудование]]),Таблица2[[#This Row],[Оборудование]]=""),"",'Спецификация для запроса ТУ'!G45)) | G34: =IF(OR(ISBLANK(Таблица2[[#This Row],[Оборудование]]),Таблица2[[#This Row],[Оборудование]]=""),"","Не задано")

Sheet Спецификация для запроса ТУ
C3: =HYPERLINK("https://gorservices.kaiten.site/",">>> Информационный ресурс ООО «НГС» (ссылка на акутальные требования и форму спецификации) <<<") -> >>> Информационный ресурс ООО «НГС» (ссылка на акутальные требования и форму спецификации) <<< | H3: Версия формы: 02.12.2025
C5: Номер БС Субарендатора (без названия) | D5: -?- | E5: Примечания по заполнению и использованию формы специфкации при отправке запроса в ООО "НГС": 1. Поиск оборудования в справочнике поддерживается в Excel 2020 и поздних версиях; 2. В случае отсутствия оборудования в справочнике необходимо приложить описание от производителя/поставщика такого оборудования к заявке, создаваемой через https://gorservices.kaiten.ru/sd; 3. Просьба перед заполнением новой спецификации обязательно проверять актуальность формы. Запросы с неактуальной спецификацией на момент создания заявки будут отклонены.
C6: Субарендатор (Оператор) | D6: -?-
C7: ID Объекта Арендатора (ООО "НГС") | D7: -?-
C9: Поиск оборудования в справочнике:
C12: Оборудование | D12: Тип оборудования | E12: Габарит, мм / Вес, кг / Кол-во портов, шт | F12: Кол-во, шт | G12: Высота подвеса, м | H12: Статус
C13: Радиочастотный кабель | D13: =IF(ISBLANK(Таблица5[[#This Row],[Оборудование]]),"-",VLOOKUP(C13,'Справочник оборудования'!B:C,2,FALSE)) -> #N/A | E13: =IF(ISBLANK(Таблица5[[#This Row],[Оборудование]]),"-",IF(D13="Кабель","-",VLOOKUP(C13,'Справочник оборудования'!B:I,8,FALSE)&" / "&VLOOKUP(C13,'Справочник оборудования'!B:I,7,FALSE)&" / "&IF(VLOOKUP(C13,'Справочник оборудования'!B:K,10,FALSE)="","-",VLOOKUP(C13,'Справочник оборудования'!B:K,10,FALSE)))) -> #N/A | F13: =IF(ISBLANK(C13),"-","-?-") -> -?- | G13: {=IFERROR(_xlfn.IFS(D13="Антенна панельная","-?-",D13="Антенна РРС","-?-"),"-")} -> - | H13: =IF(ISBLANK(C13),"-","-?-") -> -?-
C14: Оптический кабель | D14: =IF(ISBLANK(Таблица5[[#This Row],[Оборудование]]),"-",VLOOKUP(C14,'Справочник оборудования'!B:C,2,FALSE)) -> #N/A | E14: =IF(ISBLANK(Таблица5[[#This Row],[Оборудование]]),"-",IF(D14="Кабель","-",VLOOKUP(C14,'Справочник оборудования'!B:I,8,FALSE)&" / "&VLOOKUP(C14,'Справочник оборудования'!B:I,7,FALSE)&" / "&IF(VLOOKUP(C14,'Справочник оборудования'!B:K,10,FALSE)="","-",VLOOKUP(C14,'Справочник оборудования'!B:K,10,FALSE)))) -> #N/A | F14: =IF(ISBLANK(C14),"-","-?-") -> -?- | G14: {=IFERROR(_xlfn.IFS(D14="Антенна панельная","-?-",D14="Антенна РРС","-?-"),"-")} -> - | H14: =IF(ISBLANK(C14),"-","-?-") -> -?-
C15: Кабель питания (DC) | D15: =IF(ISBLANK(Таблица5[[#This Row],[Оборудование]]),"-",VLOOKUP(C15,'Справочник оборудования'!B:C,2,FALSE)) -> #N/A | E15: =IF(ISBLANK(Таблица5[[#This Row],[Оборудование]]),"-",IF(D15="Кабель","-",VLOOKUP(C15,'Справочник оборудования'!B:I,8,FALSE)&" / "&VLOOKUP(C15,'Справочник оборудования'!B:I,7,FALSE)&" / "&IF(VLOOKUP(C15,'Справочник оборудования'!B:K,10,FALSE)="","-",VLOOKUP(C15,'Справочник оборудования'!B:K,10,FALSE)))) -> #N/A | F15: =IF(ISBLANK(C15),"-","-?-") -> -?- | G15: {=IFERROR(_xlfn.IFS(D15="Антенна панельная","-?-",D15="Антенна РРС","-?-"),"-")} -> - | H15: =IF(ISBLANK(C15),"-","-?-") -> -?-
C16: Кабель управления RET | D16: =IF(ISBLANK(Таблица5[[#This Row],[Оборудование]]),"-",VLOOKUP(C16,'Справочник оборудования'!B:C,2,FALSE)) -> #N/A | E16: =IF(ISBLANK(Таблица5[[#This Row],[Оборудование]]),"-",IF(D16="Кабель","-",VLOOKUP(C16,'Справочник оборудования'!B:I,8,FALSE)&" / "&VLOOKUP(C16,'Справочник оборудования'!B:I,7,FALSE)&" / "&IF(VLOOKUP(C16,'Справочник оборудования'!B:K,10,FALSE)="","-",VLOOKUP(C16,'Справочник оборудования'!B:K,10,FALSE)))) -> #N/A | F16: =IF(ISBLANK(C16),"-","-?-") -> -?- | G16: {=IFERROR(_xlfn.IFS(D16="Антенна панельная","-?-",D16="Антенна РРС","-?-"),"-")} -> - | H16: =IF(ISBLANK(C16),"-","-?-") -> -?-
D17: =IF(ISBLANK(Таблица5[[#This Row],[Оборудование]]),"-",VLOOKUP(C17,'Справочник оборудования'!B:C,2,FALSE)) -> - | E17: =IF(ISBLANK(Таблица5[[#This Row],[Оборудование]]),"-",IF(D17="Кабель","-",VLOOKUP(C17,'Справочник оборудования'!B:I,8,FALSE)&" / "&VLOOKUP(C17,'Справочник оборудования'!B:I,7,FALSE)&" / "&IF(VLOOKUP(C17,'Справочник оборудования'!B:K,10,FALSE)="","-",VLOOKUP(C17,'Справочник оборудования'!B:K,10,FALSE)))) -> - | F17: =IF(ISBLANK(C17),"-","-?-") -> - | G17: {=IFERROR(_xlfn.IFS(D17="Антенна панельная","-?-",D17="Антенна РРС","-?-"),"-")} -> - | H17: =IF(ISBLANK(C17),"-","-?-") -> -
D18: =IF(ISBLANK(Таблица5[[#This Row],[Оборудование]]),"-",VLOOKUP(C18,'Справочник оборудования'!B:C,2,FALSE)) -> - | E18: =IF(ISBLANK(Таблица5[[#This Row],[Оборудование]]),"-",IF(D18="Кабель","-",VLOOKUP(C18,'Справочник оборудования'!B:I,8,FALSE)&" / "&VLOOKUP(C18,'Справочник оборудования'!B:I,7,FALSE)&" / "&IF(VLOOKUP(C18,'Справочник оборудования'!B:K,10,FALSE)="","-",VLOOKUP(C18,'Справочник оборудования'!B:K,10,FALSE)))) -> - | F18: =IF(ISBLANK(C18),"-","-?-") -> - | G18: {=IFERROR(_xlfn.IFS(D18="Антенна панельная","-?-",D18="Антенна РРС","-?-"),"-")} -> - | H18: =IF(ISBLANK(C18),"-","-?-") -> -
D19: =IF(ISBLANK(Таблица5[[#This Row],[Оборудование]]),"-",VLOOKUP(C19,'Справочник оборудования'!B:C,2,FALSE)) -> - | E19: =IF(ISBLANK(Таблица5[[#This Row],[Оборудование]]),"-",IF(D19="Кабель","-",VLOOKUP(C19,'Справочник оборудования'!B:I,8,FALSE)&" / "&VLOOKUP(C19,'Справочник оборудования'!B:I,7,FALSE)&" / "&IF(VLOOKUP(C19,'Справочник оборудования'!B:K,10,FALSE)="","-",VLOOKUP(C19,'Справочник оборудования'!B:K,10,FALSE)))) -> - | F19: =IF(ISBLANK(C19),"-","-?-") -> - | G19: {=IFERROR(_xlfn.IFS(D19="Антенна панельная","-?-",D19="Антенна РРС","-?-"),"-")} -> - | H19: =IF(ISBLANK(C19),"-","-?-") -> -
D20: =IF(ISBLANK(Таблица5[[#This Row],[Оборудование]]),"-",VLOOKUP(C20,'Справочник оборудования'!B:C,2,FALSE)) -> - | E20: =IF(ISBLANK(Таблица5[[#This Row],[Оборудование]]),"-",IF(D20="Кабель","-",VLOOKUP(C20,'Справочник оборудования'!B:I,8,FALSE)&" / "&VLOOKUP(C20,'Справочник оборудования'!B:I,7,FALSE)&" / "&IF(VLOOKUP(C20,'Справочник оборудования'!B:K,10,FALSE)="","-",VLOOKUP(C20,'Справочник оборудования'!B:K,10,FALSE)))) -> - | F20: =IF(ISBLANK(C20),"-","-?-") -> - | G20: {=IFERROR(_xlfn.IFS(D20="Антенна панельная","-?-",D20="Антенна РРС","-?-"),"-")} -> - | H20: =IF(ISBLANK(C20),"-","-?-") -> -
D21: =IF(ISBLANK(Таблица5[[#This Row],[Оборудование]]),"-",VLOOKUP(C21,'Справочник оборудования'!B:C,2,FALSE)) -> - | E21: =IF(ISBLANK(Таблица5[[#This Row],[Оборудование]]),"-",IF(D21="Кабель","-",VLOOKUP(C21,'Справочник оборудования'!B:I,8,FALSE)&" / "&VLOOKUP(C21,'Справочник оборудования'!B:I,7,FALSE)&" / "&IF(VLOOKUP(C21,'Справочник оборудования'!B:K,10,FALSE)="","-",VLOOKUP(C21,'Справочник оборудования'!B:K,10,FALSE)))) -> - | F21: =IF(ISBLANK(C21),"-","-?-") -> - | G21: {=IFERROR(_xlfn.IFS(D21="Антенна панельная","-?-",D21="Антенна РРС","-?-"),"-")} -> - | H21: =IF(ISBLANK(C21),"-","-?-") -> -
D22: =IF(ISBLANK(Таблица5[[#This Row],[Оборудование]]),"-",VLOOKUP(C22,'Справочник оборудования'!B:C,2,FALSE)) -> - | E22: =IF(ISBLANK(Таблица5[[#This Row],[Оборудование]]),"-",IF(D22="Кабель","-",VLOOKUP(C22,'Справочник оборудования'!B:I,8,FALSE)&" / "&VLOOKUP(C22,'Справочник оборудования'!B:I,7,FALSE)&" / "&IF(VLOOKUP(C22,'Справочник оборудования'!B:K,10,FALSE)="","-",VLOOKUP(C22,'Справочник оборудования'!B:K,10,FALSE)))) -> - | F22: =IF(ISBLANK(C22),"-","-?-") -> - | G22: {=IFERROR(_xlfn.IFS(D22="Антенна панельная","-?-",D22="Антенна РРС","-?-"),"-")} -> - | H22: =IF(ISBLANK(C22),"-","-?-") -> -
D23: =IF(ISBLANK(Таблица5[[#This Row],[Оборудование]]),"-",VLOOKUP(C23,'Справочник оборудования'!B:C,2,FALSE)) -> - | E23: =IF(ISBLANK(Таблица5[[#This Row],[Оборудование]]),"-",IF(D23="Кабель","-",VLOOKUP(C23,'Справочник оборудования'!B:I,8,FALSE)&" / "&VLOOKUP(C23,'Справочник оборудования'!B:I,7,FALSE)&" / "&IF(VLOOKUP(C23,'Справочник оборудования'!B:K,10,FALSE)="","-",VLOOKUP(C23,'Справочник оборудования'!B:K,10,FALSE)))) -> - | F23: =IF(ISBLANK(C23),"-","-?-") -> - | G23: {=IFERROR(_xlfn.IFS(D23="Антенна панельная","-?-",D23="Антенна РРС","-?-"),"-")} -> - | H23: =IF(ISBLANK(C23),"-","-?-") -> -
D24: =IF(ISBLANK(Таблица5[[#This Row],[Оборудование]]),"-",VLOOKUP(C24,'Справочник оборудования'!B:C,2,FALSE)) -> - | E24: =IF(ISBLANK(Таблица5[[#This Row],[Оборудование]]),"-",IF(D24="Кабель","-",VLOOKUP(C24,'Справочник оборудования'!B:I,8,FALSE)&" / "&VLOOKUP(C24,'Справочник оборудования'!B:I,7,FALSE)&" / "&IF(VLOOKUP(C24,'Справочник оборудования'!B:K,10,FALSE)="","-",VLOOKUP(C24,'Справочник оборудования'!B:K,10,FALSE)))) -> - | F24: =IF(ISBLANK(C24),"-","-?-") -> - | G24: {=IFERROR(_xlfn.IFS(D24="Антенна панельная","-?-",D24="Антенна РРС","-?-"),"-")} -> - | H24: =IF(ISBLANK(C24),"-","-?-") -> -
D25: =IF(ISBLANK(Таблица5[[#This Row],[Оборудование]]),"-",VLOOKUP(C25,'Справочник оборудования'!B:C,2,FALSE)) -> - | E25: =IF(ISBLANK(Таблица5[[#This Row],[Оборудование]]),"-",IF(D25="Кабель","-",VLOOKUP(C25,'Справочник оборудования'!B:I,8,FALSE)&" / "&VLOOKUP(C25,'Справочник оборудования'!B:I,7,FALSE)&" / "&IF(VLOOKUP(C25,'Справочник оборудования'!B:K,10,FALSE)="","-",VLOOKUP(C25,'Справочник оборудования'!B:K,10,FALSE)))) -> - | F25: =IF(ISBLANK(C25),"-","-?-") -> - | G25: {=IFERROR(_xlfn.IFS(D25="Антенна панельная","-?-",D25="Антенна РРС","-?-"),"-")} -> - | H25: =IF(ISBLANK(C25),"-","-?-") -> -
D26: =IF(ISBLANK(Таблица5[[#This Row],[Оборудование]]),"-",VLOOKUP(C26,'Справочник оборудования'!B:C,2,FALSE)) -> - | E26: =IF(ISBLANK(Таблица5[[#This Row],[Оборудование]]),"-",IF(D26="Кабель","-",VLOOKUP(C26,'Справочник оборудования'!B:I,8,FALSE)&" / "&VLOOKUP(C26,'Справочник оборудования'!B:I,7,FALSE)&" / "&IF(VLOOKUP(C26,'Справочник оборудования'!B:K,10,FALSE)="","-",VLOOKUP(C26,'Справочник оборудования'!B:K,10,FALSE)))) -> - | F26: =IF(ISBLANK(C26),"-","-?-") -> - | G26: {=IFERROR(_xlfn.IFS(D26="Антенна панельная","-?-",D26="Антенна РРС","-?-"),"-")} -> - | H26: =IF(ISBLANK(C26),"-","-?-") -> -
D27: =IF(ISBLANK(Таблица5[[#This Row],[Оборудование]]),"-",VLOOKUP(C27,'Справочник оборудования'!B:C,2,FALSE)) -> - | E27: =IF(ISBLANK(Таблица5[[#This Row],[Оборудование]]),"-",IF(D27="Кабель","-",VLOOKUP(C27,'Справочник оборудования'!B:I,8,FALSE)&" / "&VLOOKUP(C27,'Справочник оборудования'!B:I,7,FALSE)&" / "&IF(VLOOKUP(C27,'Справочник оборудования'!B:K,10,FALSE)="","-",VLOOKUP(C27,'Справочник оборудования'!B:K,10,FALSE)))) -> - | F27: =IF(ISBLANK(C27),"-","-?-") -> - | G27: {=IFERROR(_xlfn.IFS(D27="Антенна панельная","-?-",D27="Антенна РРС","-?-"),"-")} -> - | H27: =IF(ISBLANK(C27),"-","-?-") -> -
D28: =IF(ISBLANK(Таблица5[[#This Row],[Оборудование]]),"-",VLOOKUP(C28,'Справочник оборудования'!B:C,2,FALSE)) -> - | E28: =IF(ISBLANK(Таблица5[[#This Row],[Оборудование]]),"-",IF(D28="Кабель","-",VLOOKUP(C28,'Справочник оборудования'!B:I,8,FALSE)&" / "&VLOOKUP(C28,'Справочник оборудования'!B:I,7,FALSE)&" / "&IF(VLOOKUP(C28,'Справочник оборудования'!B:K,10,FALSE)="","-",VLOOKUP(C28,'Справочник оборудования'!B:K,10,FALSE)))) -> - | F28: =IF(ISBLANK(C28),"-","-?-") -> - | G28: {=IFERROR(_xlfn.IFS(D28="Антенна панельная","-?-",D28="Антенна РРС","-?-"),"-")} -> - | H28: =IF(ISBLANK(C28),"-","-?-") -> -
... D43: =IF(ISBLANK(Таблица5[[#This Row],[Оборудование]]),"-",VLOOKUP(C43,'Справочник оборудования'!B:C,2,FALSE)) -> - | E43: =IF(ISBLANK(Таблица5[[#This Row],[Оборудование]]),"-",IF(D43="Кабель","-",VLOOKUP(C43,'Справочник оборудования'!B:I,8,FALSE)&" / "&VLOOKUP(C43,'Справочник оборудования'!B:I,7,FALSE)&" / "&IF(VLOOKUP(C43,'Справочник оборудования'!B:K,10,FALSE)="","-",VLOOKUP(C43,'Справочник оборудования'!B:K,10,FALSE)))) -> - | F43: =IF(ISBLANK(C43),"-","-?-") -> - | G43: {=IFERROR(_xlfn.IFS(D43="Антенна панельная","-?-",D43="Антенна РРС","-?-"),"-")} -> - | H43: =IF(ISBLANK(C43),"-","-?-") -> -

Sheet Справочник оборудования
A1: # | B1: Наименование | C1: Тип оборудования | D1: Высота | E1: Ширина | F1: Глубина | G1: Диаметр | H1: Вес | I1: Габарит (текст.) | J1: Особое примечание | K1: Кол-во портов | L1: Площадь (расч.) | M1: Примечание | O1: Поиск
A2: НЕ ИМПОРТИРОВАТЬ! | B2: Ericsson Mini-Link E (0.3m) | C2: Антенна РРС | D2: НЕ ИМПОРТИРОВАТЬ! | E2: НЕ ИМПОРТИРОВАТЬ! | F2: НЕ ИМПОРТИРОВАТЬ! | G2: НЕ ИМПОРТИРОВАТЬ! | H2: 12.1 | I2: Ø 382 | J2: НЕ ИМПОРТИРОВАТЬ! | L2: 0.115 | O2: {=_xlfn._xlws.FILTER(Таблица4[Наименование],ISNUMBER(SEARCH('Спецификация для запроса ТУ'!C10,Таблица4[Наименование])),"")} -> {{table.spr_oborud}}
A3: НЕ ИМПОРТИРОВАТЬ! | B3: Ericsson Mini-Link E (0.6m) | C3: Антенна РРС | D3: НЕ ИМПОРТИРОВАТЬ! | E3: НЕ ИМПОРТИРОВАТЬ! | F3: НЕ ИМПОРТИРОВАТЬ! | G3: НЕ ИМПОРТИРОВАТЬ! | H3: 17.3 | I3: Ø 635 | J3: НЕ ИМПОРТИРОВАТЬ! | L3: 0.317 | O3: {=_xlfn._xlws.FILTER(Таблица4[Наименование],ISNUMBER(SEARCH('Спецификация для запроса ТУ'!C312,Таблица4[Наименование])),"")}
A4: НЕ ИМПОРТИРОВАТЬ! | B4: FainiTS a THP 03 370 S (0.3m) | C4: Антенна РРС | D4: НЕ ИМПОРТИРОВАТЬ! | E4: НЕ ИМПОРТИРОВАТЬ! | F4: НЕ ИМПОРТИРОВАТЬ! | G4: НЕ ИМПОРТИРОВАТЬ! | H4: 15 | I4: Ø 385 | J4: НЕ ИМПОРТИРОВАТЬ! | L4: 0.116 | O4: {=_xlfn._xlws.FILTER(Таблица4[Наименование],ISNUMBER(SEARCH('Спецификация для запроса ТУ'!C312,Таблица4[Наименование])),"")}
A5: НЕ ИМПОРТИРОВАТЬ! | B5: Huawei RTN-380AX (0.3m) | C5: Антенна РРС | D5: НЕ ИМПОРТИРОВАТЬ! | E5: НЕ ИМПОРТИРОВАТЬ! | F5: НЕ ИМПОРТИРОВАТЬ! | G5: НЕ ИМПОРТИРОВАТЬ! | H5: 8 | I5: Ø 300 | J5: НЕ ИМПОРТИРОВАТЬ! | L5: 0.071 | O5: {=_xlfn._xlws.FILTER(Таблица4[Наименование],ISNUMBER(SEARCH('Спецификация для запроса ТУ'!C312,Таблица4[Наименование])),"")}
A6: НЕ ИМПОРТИРОВАТЬ! | B6: Huawei RTN-380AX (0.6m) | C6: Антенна РРС | D6: НЕ ИМПОРТИРОВАТЬ! | E6: НЕ ИМПОРТИРОВАТЬ! | F6: НЕ ИМПОРТИРОВАТЬ! | G6: НЕ ИМПОРТИРОВАТЬ! | H6: 12 | I6: Ø 600 | J6: НЕ ИМПОРТИРОВАТЬ! | L6: 0.283 | O6: {=_xlfn._xlws.FILTER(Таблица4[Наименование],ISNUMBER(SEARCH('Спецификация для запроса ТУ'!C312,Таблица4[Наименование])),"")}
A7: НЕ ИМПОРТИРОВАТЬ! | B7: Huawei XMC-3 (0.3m) | C7: Антенна РРС | D7: НЕ ИМПОРТИРОВАТЬ! | E7: НЕ ИМПОРТИРОВАТЬ! | F7: НЕ ИМПОРТИРОВАТЬ! | G7: НЕ ИМПОРТИРОВАТЬ! | H7: 8 | I7: Ø 300 | J7: НЕ ИМПОРТИРОВАТЬ! | L7: 0.071 | M7: 42мм - толщина блока | O7: {=_xlfn._xlws.FILTER(Таблица4[Наименование],ISNUMBER(SEARCH('Спецификация для запроса ТУ'!C312,Таблица4[Наименование])),"")}
A8: НЕ ИМПОРТИРОВАТЬ! | B8: InfiLINK Evolution E5-ST23 | C8: Антенна РРС | D8: НЕ ИМПОРТИРОВАТЬ! | E8: НЕ ИМПОРТИРОВАТЬ! | F8: НЕ ИМПОРТИРОВАТЬ! | G8: НЕ ИМПОРТИРОВАТЬ! | H8: 1.8 | I8: 305 x 305 x 66 | J8: НЕ ИМПОРТИРОВАТЬ! | L8: 0.093 | O8: {=_xlfn._xlws.FILTER(Таблица4[Наименование],ISNUMBER(SEARCH('Спецификация для запроса ТУ'!C312,Таблица4[Наименование])),"")}
A9: НЕ ИМПОРТИРОВАТЬ! | B9: Infinet Vector v70-39 (0.12m, линз.) | C9: Антенна РРС | D9: НЕ ИМПОРТИРОВАТЬ! | E9: НЕ ИМПОРТИРОВАТЬ! | F9: НЕ ИМПОРТИРОВАТЬ! | G9: НЕ ИМПОРТИРОВАТЬ! | H9: 3.1 | I9: 255 x 226 x 189 | J9: НЕ ИМПОРТИРОВАТЬ! | L9: 0.058 | O9: {=_xlfn._xlws.FILTER(Таблица4[Наименование],ISNUMBER(SEARCH('Спецификация для запроса ТУ'!C312,Таблица4[Наименование])),"")}
A10: НЕ ИМПОРТИРОВАТЬ! | B10: MikroTik LGH 60G | C10: Антенна РРС | D10: НЕ ИМПОРТИРОВАТЬ! | E10: НЕ ИМПОРТИРОВАТЬ! | F10: НЕ ИМПОРТИРОВАТЬ! | G10: НЕ ИМПОРТИРОВАТЬ! | H10: 2.5 | I10: Ø 391 | J10: НЕ ИМПОРТИРОВАТЬ! | L10: 0.12 | O10: {=_xlfn._xlws.FILTER(Таблица4[Наименование],ISNUMBER(SEARCH('Спецификация для запроса ТУ'!C312,Таблица4[Наименование])),"")}
A11: НЕ ИМПОРТИРОВАТЬ! | B11: Nokia UBT-mX (0.3m) | C11: Антенна РРС | D11: НЕ ИМПОРТИРОВАТЬ! | E11: НЕ ИМПОРТИРОВАТЬ! | F11: НЕ ИМПОРТИРОВАТЬ! | G11: НЕ ИМПОРТИРОВАТЬ! | H11: 8.8 | I11: Ø 300 | J11: НЕ ИМПОРТИРОВАТЬ! | L11: 0.071 | O11: {=_xlfn._xlws.FILTER(Таблица4[Наименование],ISNUMBER(SEARCH('Спецификация для запроса ТУ'!C312,Таблица4[Наименование])),"")}
A12: НЕ ИМПОРТИРОВАТЬ! | B12: Siklu EtherHaul-8010FX (0.3m) | C12: Антенна РРС | D12: НЕ ИМПОРТИРОВАТЬ! | E12: НЕ ИМПОРТИРОВАТЬ! | F12: НЕ ИМПОРТИРОВАТЬ! | G12: НЕ ИМПОРТИРОВАТЬ! | H12: 5.3 | I12: Ø 300 | J12: НЕ ИМПОРТИРОВАТЬ! | L12: 0.071 | O12: {=_xlfn._xlws.FILTER(Таблица4[Наименование],ISNUMBER(SEARCH('Спецификация для запроса ТУ'!C312,Таблица4[Наименование])),"")}
A13: НЕ ИМПОРТИРОВАТЬ! | B13: Siklu EtherHaul-8010FX (0.6m) | C13: Антенна РРС | D13: НЕ ИМПОРТИРОВАТЬ! | E13: НЕ ИМПОРТИРОВАТЬ! | F13: НЕ ИМПОРТИРОВАТЬ! | G13: НЕ ИМПОРТИРОВАТЬ! | H13: 16 | I13: Ø 600 | J13: НЕ ИМПОРТИРОВАТЬ! | L13: 0.283 | O13: {=_xlfn._xlws.FILTER(Таблица4[Наименование],ISNUMBER(SEARCH('Спецификация для запроса ТУ'!C312,Таблица4[Наименование])),"")}
A14: НЕ ИМПОРТИРОВАТЬ! | B14: МАЯК-1000Е 0.12m (линз.) | C14: Антенна РРС | D14: НЕ ИМПОРТИРОВАТЬ! | E14: НЕ ИМПОРТИРОВАТЬ! | F14: НЕ ИМПОРТИРОВАТЬ! | G14: НЕ ИМПОРТИРОВАТЬ! | H14: 4.8 | I14: Ø 120 | J14: НЕ ИМПОРТИРОВАТЬ! | L14: 0.084 | O14: {=_xlfn._xlws.FILTER(Таблица4[Наименование],ISNUMBER(SEARCH('Спецификация для запроса ТУ'!C312,Таблица4[Наименование])),"")}
A15: НЕ ИМПОРТИРОВАТЬ! | B15: МАЯК-1000Е 0.3m | C15: Антенна РРС | D15: НЕ ИМПОРТИРОВАТЬ! | E15: НЕ ИМПОРТИРОВАТЬ! | F15: НЕ ИМПОРТИРОВАТЬ! | G15: НЕ ИМПОРТИРОВАТЬ! | H15: 7 | I15: Ø 385 | J15: НЕ ИМПОРТИРОВАТЬ! | L15: 0.116 | O15: {=_xlfn._xlws.FILTER(Таблица4[Наименование],ISNUMBER(SEARCH('Спецификация для запроса ТУ'!C312,Таблица4[Наименование])),"")}
A16: НЕ ИМПОРТИРОВАТЬ! | B16: МАЯК-1000Е 0.6m | C16: Антенна РРС | D16: НЕ ИМПОРТИРОВАТЬ! | E16: НЕ ИМПОРТИРОВАТЬ! | F16: НЕ ИМПОРТИРОВАТЬ! | G16: НЕ ИМПОРТИРОВАТЬ! | H16: 10.4 | I16: Ø 650 | J16: НЕ ИМПОРТИРОВАТЬ! | L16: 0.332 | O16: {=_xlfn._xlws.FILTER(Таблица4[Наименование],ISNUMBER(SEARCH('Спецификация для запроса ТУ'!C312,Таблица4[Наименование])),"")}
A17: НЕ ИМПОРТИРОВАТЬ! | B17: НТР NTSR-1G A20/А25 (0.12m) | C17: Антенна РРС | D17: НЕ ИМПОРТИРОВАТЬ! | E17: НЕ ИМПОРТИРОВАТЬ! | F17: НЕ ИМПОРТИРОВАТЬ! | G17: НЕ ИМПОРТИРОВАТЬ! | H17: 5.6 | I17: Ø 125 | J17: НЕ ИМПОРТИРОВАТЬ! | L17: 0.144 | O17: {=_xlfn._xlws.FILTER(Таблица4[Наименование],ISNUMBER(SEARCH('Спецификация для запроса ТУ'!C312,Таблица4[Наименование])),"")}
A18: НЕ ИМПОРТИРОВАТЬ! | B18: НТР NTSR-1G AWG 0.3 | C18: Антенна РРС | D18: НЕ ИМПОРТИРОВАТЬ! | E18: НЕ ИМПОРТИРОВАТЬ! | F18: НЕ ИМПОРТИРОВАТЬ! | G18: НЕ ИМПОРТИРОВАТЬ! | H18: 14.8 | I18: Ø 395 | J18: НЕ ИМПОРТИРОВАТЬ! | L18: 0.123 | O18: {=_xlfn._xlws.FILTER(Таблица4[Наименование],ISNUMBER(SEARCH('Спецификация для запроса ТУ'!C312,Таблица4[Наименование])),"")}
A19: НЕ ИМПОРТИРОВАТЬ! | B19: НТР NTSR-1G AWG 0.6 | C19: Антенна РРС | D19: НЕ ИМПОРТИРОВАТЬ! | E19: НЕ ИМПОРТИРОВАТЬ! | F19: НЕ ИМПОРТИРОВАТЬ! | G19: НЕ ИМПОРТИРОВАТЬ! | H19: 16.8 | I19: Ø 650 | J19: НЕ ИМПОРТИРОВАТЬ! | L19: 0.332 | O19: {=_xlfn._xlws.FILTER(Таблица4[Наименование],ISNUMBER(SEARCH('Спецификация для запроса ТУ'!C312,Таблица4[Наименование])),"")}
A20: НЕ ИМПОРТИРОВАТЬ! | B20: РРС 0.2m | C20: Антенна РРС | D20: НЕ ИМПОРТИРОВАТЬ! | E20: НЕ ИМПОРТИРОВАТЬ! | F20: НЕ ИМПОРТИРОВАТЬ! | G20: НЕ ИМПОРТИРОВАТЬ! | H20: 6 | I20: Ø 200 | J20: НЕ ИМПОРТИРОВАТЬ! | L20: 0.031 | O20: {=_xlfn._xlws.FILTER(Таблица4[Наименование],ISNUMBER(SEARCH('Спецификация для запроса ТУ'!C312,Таблица4[Наименование])),"")}
A21: НЕ ИМПОРТИРОВАТЬ! | B21: РРС 0.3m | C21: Антенна РРС | D21: НЕ ИМПОРТИРОВАТЬ! | E21: НЕ ИМПОРТИРОВАТЬ! | F21: НЕ ИМПОРТИРОВАТЬ! | G21: НЕ ИМПОРТИРОВАТЬ! | H21: 9 | I21: Ø 300 | J21: НЕ ИМПОРТИРОВАТЬ! | L21: 0.071 | O21: {=_xlfn._xlws.FILTER(Таблица4[Наименование],ISNUMBER(SEARCH('Спецификация для запроса ТУ'!C312,Таблица4[Наименование])),"")}
A22: НЕ ИМПОРТИРОВАТЬ! | B22: РРС 0.6m | C22: Антенна РРС | D22: НЕ ИМПОРТИРОВАТЬ! | E22: НЕ ИМПОРТИРОВАТЬ! | F22: НЕ ИМПОРТИРОВАТЬ! | G22: НЕ ИМПОРТИРОВАТЬ! | H22: 12 | I22: Ø 600 | J22: НЕ ИМПОРТИРОВАТЬ! | L22: 0.283 | O22: {=_xlfn._xlws.FILTER(Таблица4[Наименование],ISNUMBER(SEARCH('Спецификация для запроса ТУ'!C312,Таблица4[Наименование])),"")}
A23: НЕ ИМПОРТИРОВАТЬ! | B23: Broadradio LLPX310P2-DH2-2C | C23: Антенна панельная | D23: НЕ ИМПОРТИРОВАТЬ! | E23: НЕ ИМПОРТИРОВАТЬ! | F23: НЕ ИМПОРТИРОВАТЬ! | G23: НЕ ИМПОРТИРОВАТЬ! | H23: 18.2 | I23: 1380 x 320 x 140 | J23: НЕ ИМПОРТИРОВАТЬ! | K23: 8 | L23: 0.442 | M23: (1710-2170/1710-2170/2490-2690/2490-2690) | O23: {=_xlfn._xlws.FILTER(Таблица4[Наименование],ISNUMBER(SEARCH('Спецификация для запроса ТУ'!C312,Таблица4[Наименование])),"")}
A24: НЕ ИМПОРТИРОВАТЬ! | B24: Broadradio LLPX312P-DHH-E2-C | C24: Антенна панельная | D24: НЕ ИМПОРТИРОВАТЬ! | E24: НЕ ИМПОРТИРОВАТЬ! | F24: НЕ ИМПОРТИРОВАТЬ! | G24: НЕ ИМПОРТИРОВАТЬ! | H24: 25.7 | I24: 1370 x 339 x 169 | J24: НЕ ИМПОРТИРОВАТЬ! | K24: 8 | L24: 0.464 | M24: (1710-2170/1710-2170/2490-2690/2490-2690) | O24: {=_xlfn._xlws.FILTER(Таблица4[Наименование],ISNUMBER(SEARCH('Спецификация для запроса ТУ'!C312,Таблица4[Наименование])),"")}
A25: НЕ ИМПОРТИРОВАТЬ! | B25: Broadradio S-HLLPX8.6P2-DH2-2C | C25: Антенна панельная | D25: НЕ ИМПОРТИРОВАТЬ! | E25: НЕ ИМПОРТИРОВАТЬ! | F25: НЕ ИМПОРТИРОВАТЬ! | G25: НЕ ИМПОРТИРОВАТЬ! | H25: 30.9 | I25: 1295 x 448 x 145 | J25: НЕ ИМПОРТИРОВАТЬ! | K25: 8 | L25: 0.58 | M25: (1710-2170/1710-2170/2490-2690/2490-2690) | O25: {=_xlfn._xlws.FILTER(Таблица4[Наименование],ISNUMBER(SEARCH('Спецификация для запроса ТУ'!C312,Таблица4[Наименование])),"")}
A26: НЕ ИМПОРТИРОВАТЬ! | B26: Broadradio U2L4PX305.11P-DHH-E2-C | C26: Антенна панельная | D26: НЕ ИМПОРТИРОВАТЬ! | E26: НЕ ИМПОРТИРОВАТЬ! | F26: НЕ ИМПОРТИРОВАТЬ! | G26: НЕ ИМПОРТИРОВАТЬ! | H26: 38.9 | I26: 1495 x 498 x 197 | J26: НЕ ИМПОРТИРОВАТЬ! | K26: 16 | L26: 0.745 | M26: (694-960/694-960/1710-2170/1710-2170/2490-2690/2490-2690/1710-2690/1710-2690) | O26: {=_xlfn._xlws.FILTER(Таблица4[Наименование],ISNUMBER(SEARCH('Спецификация для запроса ТУ'!C312,Таблица4[Наименование])),"")}
A27: НЕ ИМПОРТИРОВАТЬ! | B27: Broadradio U2L4PX305.11P2-DHH-E2-C | C27: Антенна панельная | D27: НЕ ИМПОРТИРОВАТЬ! | E27: НЕ ИМПОРТИРОВАТЬ! | F27: НЕ ИМПОРТИРОВАТЬ! | G27: НЕ ИМПОРТИРОВАТЬ! | H27: 38.9 | I27: 1495 x 498 x 197 | J27: НЕ ИМПОРТИРОВАТЬ! | K27: 16 | L27: 0.745 | M27: (694-960/694-960/1710-2170/1710-2170/2490-2690/2490-2690/1710-2690/1710-2690) | O27: {=_xlfn._xlws.FILTER(Таблица4[Наименование],ISNUMBER(SEARCH('Спецификация для запроса ТУ'!C312,Таблица4[Наименование])),"")}
A28: НЕ ИМПОРТИРОВАТЬ! | B28: Broadradio UL4PX308.10P-E2-C | C28: Антенна панельная | D28: НЕ ИМПОРТИРОВАТЬ! | E28: НЕ ИМПОРТИРОВАТЬ! | F28: НЕ ИМПОРТИРОВАТЬ! | G28: НЕ ИМПОРТИРОВАТЬ! | H28: 41.3 | I28: 2400 x 339 x 169 | J28: НЕ ИМПОРТИРОВАТЬ! | K28: 10 | L28: 0.814 | M28: (698-960/1710-2690/1710-2690/1710-2690/1710-2690) | O28: {=_xlfn._xlws.FILTER(Таблица4[Наименование],ISNUMBER(SEARCH('Спецификация для запроса ТУ'!C312,Таблица4[Наименование])),"")}
A29: НЕ ИМПОРТИРОВАТЬ! | B29: Comba ODDI2-032R18J02-GQ V1 | C29: Антенна панельная | D29: НЕ ИМПОРТИРОВАТЬ! | E29: НЕ ИМПОРТИРОВАТЬ! | F29: НЕ ИМПОРТИРОВАТЬ! | G29: НЕ ИМПОРТИРОВАТЬ! | H29: 35 | I29: 1800 x 355 x 192 | J29: НЕ ИМПОРТИРОВАТЬ! | K29: 8 | L29: 0.639 | M29: (1695-2690/1695-2690/1695-2690/1695-2690) (вес не точный) | O29: {=_xlfn._xlws.FILTER(Таблица4[Наименование],ISNUMBER(SEARCH('Спецификация для запроса ТУ'!C312,Таблица4[Наименование])),"")}
A30: НЕ ИМПОРТИРОВАТЬ! | B30: Comba ODHI-32R18JJ65R16M-GQ | C30: Антенна панельная | D30: НЕ ИМПОРТИРОВАТЬ! | E30: НЕ ИМПОРТИРОВАТЬ! | F30: НЕ ИМПОРТИРОВАТЬ! | G30: НЕ ИМПОРТИРОВАТЬ! | H30: 40.6 | I30: 2000 x 355 x 192 | J30: НЕ ИМПОРТИРОВАТЬ! | K30: 10 | L30: 0.71 | M30: (690-960/1710-2690/1710-2690/1710-2690/1710-2690) | O30: {=_xlfn._xlws.FILTER(Таблица4[Наименование],ISNUMBER(SEARCH('Спецификация для запроса ТУ'!C312,Таблица4[Наименование])),"")}
A31: НЕ ИМПОРТИРОВАТЬ! | B31: Comba ODI-065R15M18J02-Q V3 | C31: Антенна панельная | D31: НЕ ИМПОРТИРОВАТЬ! | E31: НЕ ИМПОРТИРОВАТЬ! | F31: НЕ ИМПОРТИРОВАТЬ! | G31: НЕ ИМПОРТИРОВАТЬ! | H31: 26 | I31: 1500 x 445 x 150 | J31: НЕ ИМПОРТИРОВАТЬ! | K31: 8 | L31: 0.668 | M31: (690-960/690-960/1695-2690/1695-2690) | O31: {=_xlfn._xlws.FILTER(Таблица4[Наименование],ISNUMBER(SEARCH('Спецификация для запроса ТУ'!C312,Таблица4[Наименование])),"")}
A32: НЕ ИМПОРТИРОВАТЬ! | B32: Comba ODI-065R15M18JJ02-GQ V1 | C32: Антенна панельная | D32: НЕ ИМПОРТИРОВАТЬ! | E32: НЕ ИМПОРТИРОВАТЬ! | F32: НЕ ИМПОРТИРОВАТЬ! | G32: НЕ ИМПОРТИРОВАТЬ! | H32: 19.7 | I32: 1400 x 320 x 145 | J32: НЕ ИМПОРТИРОВАТЬ! | K32: 6 | L32: 0.448 | M32: (690-960/1695-2690/1695-2690) | O32: {=_xlfn._xlws.FILTER(Таблица4[Наименование],ISNUMBER(SEARCH('Спецификация для запроса ТУ'!C312,Таблица4[Наименование])),"")}
A33: НЕ ИМПОРТИРОВАТЬ! | B33: Comba ODI-065R15MJJJJ02-Q-22 V1 | C33: Антенна панельная | D33: НЕ ИМПОРТИРОВАТЬ! | E33: НЕ ИМПОРТИРОВАТЬ! | F33: НЕ ИМПОРТИРОВАТЬ! | G33: НЕ ИМПОРТИРОВАТЬ! | H33: 25.5 | I33: 1600 x 355 x 192 | J33: НЕ ИМПОРТИРОВАТЬ! | K33: 10 | L33: 0.568 | M33: (690-960/1695-2690/1695-2690/1695-2690/1695-2690) | O33: {=_xlfn._xlws.FILTER(Таблица4[Наименование],ISNUMBER(SEARCH('Спецификация для запроса ТУ'!C312,Таблица4[Наименование])),"")}
A34: НЕ ИМПОРТИРОВАТЬ! | B34: Comba ODI-065R15MJJJJ02-Q-RU V1 | C34: Антенна панельная | D34: НЕ ИМПОРТИРОВАТЬ! | E34: НЕ ИМПОРТИРОВАТЬ! | F34: НЕ ИМПОРТИРОВАТЬ! | G34: НЕ ИМПОРТИРОВАТЬ! | H34: 29.3 | I34: 1600 x 355 x 192 | J34: НЕ ИМПОРТИРОВАТЬ! | K34: 10 | L34: 0.568 | M34: (690-960/1695-2690/1695-2690/1695-2690/1695-2690) | O34: {=_xlfn._xlws.FILTER(Таблица4[Наименование],ISNUMBER(SEARCH('Спецификация для запроса ТУ'!C312,Таблица4[Наименование])),"")}
A35: НЕ ИМПОРТИРОВАТЬ! | B35: Comba ODI-065R16M17JJJJ02-Q V3 | C35: Антенна панельная | D35: НЕ ИМПОРТИРОВАТЬ! | E35: НЕ ИМПОРТИРОВАТЬ! | F35: НЕ ИМПОРТИРОВАТЬ! | G35: НЕ ИМПОРТИРОВАТЬ! | H35: 26.5 | I35: 1800 x 355 x 192 | J35: НЕ ИМПОРТИРОВАТЬ! | K35: 10 | L35: 0.639 | M35: (690-960/1695-2690/1695-2690/1695-2690/1695-2690) | O35: {=_xlfn._xlws.FILTER(Таблица4[Наименование],ISNUMBER(SEARCH('Спецификация для запроса ТУ'!C312,Таблица4[Наименование])),"")}
A36: НЕ ИМПОРТИРОВАТЬ! | B36: Comba ODI-065R16M18JJ-GQ V3 | C36: Антенна панельная | D36: НЕ ИМПОРТИРОВАТЬ! | E36: НЕ ИМПОРТИРОВАТЬ! | F36: НЕ ИМПОРТИРОВАТЬ! | G36: НЕ ИМПОРТИРОВАТЬ! | H36: 31.2 | I36: 2000 x 355 x 192 | J36: НЕ ИМПОРТИРОВАТЬ! | K36: 6 | L36: 0.71 | M36: (694-960/1695-2690/1695-2690) | O36: {=_xlfn._xlws.FILTER(Таблица4[Наименование],ISNUMBER(SEARCH('Спецификация для запроса ТУ'!C312,Таблица4[Наименование])),"")}
A37: НЕ ИМПОРТИРОВАТЬ! | B37: Comba ODI-065R16M18JJ-GQ-RU V2 | C37: Антенна панельная | D37: НЕ ИМПОРТИРОВАТЬ! | E37: НЕ ИМПОРТИРОВАТЬ! | F37: НЕ ИМПОРТИРОВАТЬ! | G37: НЕ ИМПОРТИРОВАТЬ! | H37: 31.1 | I37: 2000 x 355 x 192 | J37: НЕ ИМПОРТИРОВАТЬ! | K37: 6 | L37: 0.71 | M37: (694-960/1695-2690/1695-2690) | O37: {=_xlfn._xlws.FILTER(Таблица4[Наименование],ISNUMBER(SEARCH('Спецификация для запроса ТУ'!C312,Таблица4[Наименование])),"")}
A38: НЕ ИМПОРТИРОВАТЬ! | B38: Comba ODI2-065R16MJJ02-GQ V1 | C38: Антенна панельная | D38: НЕ ИМПОРТИРОВАТЬ! | E38: НЕ ИМПОРТИРОВАТЬ! | F38: НЕ ИМПОРТИРОВАТЬ! | G38: НЕ ИМПОРТИРОВАТЬ! | H38: 43.7 | I38: 2000 x 445 x 192 | J38: НЕ ИМПОРТИРОВАТЬ! | K38: 12 | L38: 0.89 | M38: (690-960/690-960/1695-2690/1695-2690/1695-2690/1695-2690) | O38: {=_xlfn._xlws.FILTER(Таблица4[Наименование],ISNUMBER(SEARCH('Спецификация для запроса ТУ'!C312,Таблица4[Наименование])),"")}
A39: НЕ ИМПОРТИРОВАТЬ! | B39: Comba ODV2-065R18J-G V1 | C39: Антенна панельная | D39: НЕ ИМПОРТИРОВАТЬ! | E39: НЕ ИМПОРТИРОВАТЬ! | F39: НЕ ИМПОРТИРОВАТЬ! | G39: НЕ ИМПОРТИРОВАТЬ! | H39: 23.1 | I39: 1400 x 320 x 110 | J39: НЕ ИМПОРТИРОВАТЬ! | K39: 4 | L39: 0.448 | M39: (1710-2690/1710-2690/1710-2690/1710-2690) | O39: {=_xlfn._xlws.FILTER(Таблица4[Наименование],ISNUMBER(SEARCH('Спецификация для запроса ТУ'!C312,Таблица4[Наименование])),"")}
A40: НЕ ИМПОРТИРОВАТЬ! | B40: Commscope VVPX306R-V1 | C40: Антенна панельная | D40: НЕ ИМПОРТИРОВАТЬ! | E40: НЕ ИМПОРТИРОВАТЬ! | F40: НЕ ИМПОРТИРОВАТЬ! | G40: НЕ ИМПОРТИРОВАТЬ! | H40: 9 | I40: 812 x 290 x 103 | J40: НЕ ИМПОРТИРОВАТЬ! | K40: 4 | L40: 0.235 | M40: (1710-2690/1710-2690) | O40: {=_xlfn._xlws.FILTER(Таблица4[Наименование],ISNUMBER(SEARCH('Спецификация для запроса ТУ'!C312,Таблица4[Наименование])),"")}
...

Sheet Справочник Статусов
A1: Субарендатор | B1: Статус размещения | C1: Способ установки / прокладки
A2: -?- | B2: -?- | C2: Не задано
A3: ПАО "ВымпелКом" | B3: Зарезервировано (запрошено) | C3: Одиночно
A4: ПАО "МТС" | B4: Зарезервировано (демонтаж в развитии) | C4: Совмещённо
A5: ПАО "МегаФон" | B5: Зарезервировано (перенос в развитии) | C5: Кассетно (Ericsson)
A6: ООО "Т2 Мобайл" | B6: Размещено | C6: Стэком (Nokia)
B7: Размещено (демонтаж в развитии) | C7: Комбинированно (Huawei)
B8: Размещено (перенос в развитии) | C8: Внутри ОДН
B9: Подлежит демонтажу | C9: Снаружи ОДН
B10: Демонтировано | C10: В коробе
B11: Перенесено
B12: В развитии (резерв)
B13: Кабели
B14: -
